# 异常处理

## 1、异常处理结构

 C++引入**try、throw和catch**三个用于异常处理的关键字。Try用于检测可能发生的异常，throw用于抛出异常，catch用于捕获并处理由throw抛出的异常。Try-throw-catch构造了C++异常处理的基本结构。

  Try块中放置的是可能产生错误的程序代码，在其中对那些可能出现异常的语句进行测试，并根据测试结果决定是否抛出throw异常。Throw exception抛出异常。Exception就是异常，它可以是任何数据类型的表达式，包括类对象。Throw将利用exception生成一个临时的异常对象，然后将其抛出，该异常对象能够被catch捕获并处理。

  Catch必须紧跟在try块后面，用于捕获由throw抛出的异常。同一try块可以抛出多个不同类型的异常，而每个catch块则只能处理一种类型的异常。因此，当一个try块抛出了多个不同类型的异常时，就应该有多个catch异常处理块与之对应。

  Catch后面的参数括号中只能有单个类型或单个对象声明，称为异常声明。Type1，type2，typem是数据类型关键字，它可以是系统内置的数据类型，也可以是用户自定义的数据类型，如类或结构。在catch的参数表中，可以只有类型名而没有形式参数。

```c++
try{
 ……             //try程序块
if  err1  throw xx1
 ……
if  err2  throw xx2
 ……
if  errn  throw xxn
  }
catch(type1  arg){……}   //异常类型1错误处理
catch(type2  arg){……}   //异常类型2错误处理
catch(typem  arg){……}  //异常类型m错误处理
  …… 
```

* try-throw-catch异常处理的执行逻辑

  * 当程序执行过程中遇到try块时，将进入try块并按正常的程序逻辑顺序执行其中的语句。

  * 如果try块的所有语句都被正常执行，没有发生任何异常，那么try块中就不会有异常被throw。在这种情况下，程序将忽略所有的catch块，顺序执行那些不属于任何catch块的程序语句，并按正常逻辑结束程序的执行，就像catch块不存在一样。

  * 如果在执行try块的过程中，某条语句产生错误并用throw抛出了异常，则程序控制流程将自此throw子句转移到catch块，try块中该throw语句之后的所有语句都不会再被执行了。

  * C++将按catch块出现的次序，用异常的数据类型与每个catch参数表中指定的数据类型相比较，如果两者类型相同，就执行该catch块，同时还将把异常的值传递给catch块中的形参arg（如果该块有arg形参）。只要有一个catch块捕获了异常，其余catch块都将被忽略。

  * 如果没有任何catch能够匹配该异常，C++将调用系统默认的异常处理程序处理该异常，其通常做法是直接终止该程序的运行。

* **抛出异常**：如果程序发生异常情况，而在当前环境中获取不到异常处理的足够信息，可以将异常抛出。抛出异常的含义，如图所示。

  ![img](https://p.ananas.chaoxing.com/star3/origin/be241e2b8a5c578e94b3d8abbfc7a69d.png)

  当一段程序中发现错误数据，但是该程序不知道如何处理时，可以抛出异常。在C++中，使用throw来抛出异常。抛出异常的语法如图所示。

  ![img](https://p.ananas.chaoxing.com/star3/origin/9568afecae08da3345fe6cbe49fa3afd.png)

  将上述除数为0的程序处理，当用户输入除数为0时抛出异常，代码及结果如图所示。

  ![img](https://p.ananas.chaoxing.com/star3/origin/bc9f042437ecafe7c1a4e0dc7b0f935c.png)

  当用户使用throw语句抛出异常时，可以避免程序出现运行错误。但是，如果只有异常的抛出，程序将中途退出，这也是具体程序设计中不允许的，为此，C++引入了异常的捕获和处理机制。

* catch捕获异常

   捕获异常由catch完成，catch必须紧跟在与之对应的try块后面。如果异常被某catch捕获，程序将执行该catch块中的代码，之后将继续执行catch块后面的语句；如果异常不能被任何catch块捕获，它将被传递给系统的异常处理模块，程序将被系统异常处理模块终止。catch根据异常的数据类型捕获异常，如果catch参数表中异常声明的数据类型与throw抛出的异常的数据类型相同，该catch块将捕获异常。

  **注意：**catch在进行异常数据类型的匹配时，**不会进行数据类型的默认转换**，只有与异常的数据类型精确匹配的catch块才会被执行。

  ![img](https://p.ananas.chaoxing.com/star3/origin/707c24f8885beb53ea4821c0129da027.png)

  ```c++
  #include<iostream>
  using namespace std;
  void main(){
  cout<<"1--befroe try block..."<<endl;
  try{
       cout<<"2--Inside try block..."<<endl;
       throw 10;                        
       cout<<"3--After throw ...."<<endl;
   }
  catch(double i) { 
       cout<<"4--In catch block1 .. an int type is.."<<i<<endl;
  }
        cout<<"5--After Catch...";
    }
  ```

  从运行结果可以看出，当程序执行了try块中的throw 10语句后就被中止了，没有执行catch块及catch后的语句。原因是throw 10抛出的是一个int类型的异常，而catch（double i）只能捕获double类型的异常。虽然int可以转换成double类型的数据，但catch并不会进行这样的转换。所以例子中没有适当的catch块能够处理try块中抛出的异常。该异常最后只能由系统的异常处理模块处理，系统异常处理模块中止了改程序的执行。

## 2、异常与函数

* 在函数中处理异常

  ```c++
  //temperature是一个检测温度异常的函数，当温度达到冰点或沸点时产生异常
  #include<iostream>
  using namespace std;
  void temperature(int t)
  {
      try{
          if(t==100) throw "沸点！";
          else if(t==0) throw "冰点！";
          else cout<<"the temperature is OK..."<<endl;
      }
      catch(int x){cout<<"temperatore="<<x<<endl;}
      catch(char *s){cout<<s<<endl;}
  }
  void main(){
      temperature(0);								//L1
      temperature(10);							//L2
      temperature(100);							//L3
  }
  ```

  Temperature是一个具有异常处理能力的函数，当调用参数为0或100时将产生字符串类型的异常，catch将捕获该异常并进行处理。

  **注意**：在函数内部进行异常处理时，针对try块抛出的所有异常都应该提供对应的catch块对之进行处理；否则，若在调用函数时发生了不能够处理的异常，程序将会被中止。如在例子中，若将catch（char s）修改为catch（double s），则当调用语句L1时，程序就会被系统中止。因为temperature（0）将产生char类型的异常（由语句throw冰点！产生），但函数却没有能够捕获char类型异常的catch块，最后就会被系统异常处理模块中止。

* 在函数调用中处理异常

  将产生异常的程序代码放在一个函数中，将检测处理异常的函数代码放在另一个函数中，能让异常处理更具灵活性和实用性。

  ```c++
  //异常处理从函数中独立出来，由调用函数完成
  #include<iostream>
  using namespace std;
  void temperature(int t) {
      if(t==100)  throw "沸点！";
      else if(t==0)  throw "冰点！";
      else  cout<<"the temperature is ..."<<t<<endl;
  }
  void main(){
      try{
          temperature(10);
          temperature(50);
          temperature(100);
      }
      catch(char *s){cout<<s<<endl;}
  }
  ```

## 3、异常与类

由于构造函数没有返回类型，在执行构造函数过程中若出现异常，传统处理方法可能是：

* 返回一个处于错误状态的对象，外部程序可以检查该对象状态，以便判定该对象是否被成功构造。

* 设置一个全局变量保存对象构造的状态，外部程序可以通过该变量值判断对象构造的情况。

* 在构造函数中不做对象的初始化工作，而是专门设计一个成员函数负责对象的初始化。

  C++中异常处理机制能够很好地处理构造函数中的异常问题，当构造函数出现错误时就抛出异常，外部函数可以在构造函数之外捕获并处理该异常。

```c++
//类B有一个类A的对象成员数组obj，类B的构造函数进行了自由存储空间的过量申请，
//最后造成内存资源耗尽产生异常，则异常将调用对象成员数组obj的析构函数，回收obj占用的存储空间
#include<iostream>
using namespace std;
class A{
    int a;
public:
    A(int i=0):a(i){}
    ~A(){cout<<"in A destructor..."<<endl;}
};
class B{
    A obj[3];
    double *pb[10];
public:
    B(int k){
     cout<<"in B constructor..."<<endl;
     for (int i=0;i<20;i++){
      pb[i]=new double[2];
      if(i==3)
         throw i;
      else 
         cout<<"Allocated 2 doubles in pb["<<i<<"]"<<endl;
}
    }
};
void main(){
   try{B b(2);}
   catch(int e){ cout<<"catch an exception when allocated pb["    <<e<<"]"<<endl;   }
}
```

从程序运行结果可以看出，类B构造函数中的循环正常运行了3次，pb[0]-pb[2]都分配到了相应的数组空间。当进行第4次循环为pb[3]分配数组空间时产生异常，C++异常处理机制将调用异常发生前已构造了的obj对象成员数组中每个对象的析构函数，这就是运行结果中有3行in A destructor…的由来。